<?xml version="1.0"?>

<robot xmlns:sensor="http://playerstage.sourceforge.net/gazebo/xmlschema/#sensor"
       xmlns:controller="http://playerstage.sourceforge.net/gazebo/xmlschema/#controller"
       xmlns:interface="http://playerstage.sourceforge.net/gazebo/xmlschema/#interface"
       xmlns:xacro="http://ros.org/wiki/xacro"
name="pioneer3at">

<!-- Chassis -->
    <link name="base_link">
        <inertial>
            <mass value="21.5"/>
            <origin xyz="-0.1 0 0.177"/>
            <inertia ixx="0.3338" ixy="0.0" ixz="0.0"
                              iyy="0.4783" iyz="0.0"
                                            izz="0.3338"/>
        </inertial>
        <visual>
            <origin xyz="0 0 0.177" rpy="0 0 0"/>
            <geometry name="pioneer_geom">
                <mesh filename="package://amr_robots_description/meshes/p3at_meshes/chassis.stl"/>
            </geometry>
            <material name="ChassisRed">
                <color rgba="0.851 0.0 0.0 1.0"/>
            </material>
        </visual>
        <collision>
            <origin xyz="0 0 0.177" rpy="0 0 0"/>
            <geometry>
                <mesh filename="package://amr_robots_description/meshes/p3at_meshes/chassis.stl"/>
            </geometry>
        </collision>
    </link>
    <gazebo reference="base_link">
        <material value="Gazebo/Red"/>
    </gazebo>

<!-- Top -->
    <link name="top_plate">
        <inertial>
            <mass value="0.1"/>	
            <origin xyz="-0.025 0 -0.223"/>
            <inertia ixx="1.0" ixy="0.0" ixz="0.0"
                 iyy="1.0" iyz="0.0" izz="1.0"/>
        </inertial>
        <visual>
            <origin xyz="0 0 0" rpy="0 0 0"/>
            <geometry name="pioneer_geom">
                <mesh filename="package://amr_robots_description/meshes/p3at_meshes/top.stl"/>
            </geometry>
            <material name="TopBlack">
                <color rgba="0.038 0.038 0.038 1.0"/>
            </material>
        </visual>
    </link>
    <gazebo reference="top_plate">
        <material>Gazebo/Black</material>
    </gazebo>

    <joint name="base_top_joint" type="fixed">
        <origin xyz="0.003 0 0.274" rpy="0 0 0"/>
        <parent link="base_link"/>
        <child link="top_plate"/>
    </joint>

<!-- Front + Back Sonar -->
    <link name="front_sonar">
        <inertial>
            <mass value="0.1"/>	
            <origin xyz="0 0 0"/>
            <inertia ixx="1.0" ixy="0.0" ixz="0.0"
                 iyy="1.0" iyz="0.0" izz="1.0"/>
        </inertial>
        <visual>
            <origin xyz="0 0 0" rpy="0 0 0"/>
            <geometry name="pioneer_geom">
                <mesh filename="package://amr_robots_description/meshes/p3at_meshes/front_sonar.stl"/>
            </geometry>
            <material name="SonarYellow">
                <color rgba="0.715 0.583 0.210 1.0"/>
            </material>
        </visual>
    </link>
    <gazebo reference="front_sonar">
        <material value="Gazebo/Yellow"/>
    </gazebo>

    <joint name="base_front_joint" type="fixed">
        <origin xyz="0.193 0 0.25" rpy="0 0 0"/>
        <parent link="base_link"/>
        <child link="front_sonar"/>
    </joint>

    <link name="back_sonar">
        <inertial>
            <mass value="0.1"/>	
            <origin xyz="0 0 0"/>
            <inertia ixx="1.0" ixy="0.0" ixz="0.0"
                 iyy="1.0" iyz="0.0" izz="1.0"/>
        </inertial>
        <visual>
            <origin xyz="0 0 0" rpy="0 0 0"/>
            <geometry name="pioneer_geom">
                <mesh filename="package://amr_robots_description/meshes/p3at_meshes/back_sonar.stl"/>
            </geometry>
            <material name="SonarYellow">
                <color rgba="0.715 0.583 0.210 1.0"/>
            </material>
        </visual>
    </link>
    <gazebo reference="back_sonar">
        <material value="Gazebo/Yellow"/>
    </gazebo>

    <joint name="base_back_joint" type="fixed">
        <origin xyz="-0.187 0 0.247" rpy="0 0 0"/>
        <parent link="base_link"/>
        <child link="back_sonar"/>
    </joint>

<xacro:macro name="p3at_drive_side" params="side reflect">

  <link name="p3at_back_${side}_wheel">
    <inertial>
      <mass value="1.5"/>
      <origin xyz="0 0 0"/>
      <inertia ixx="0.012411765597" ixy="0" ixz="0"
               iyy="0.015218160428" iyz="0" izz="0.011763977943"/>
    </inertial>
    <visual>
      <origin xyz="0 0 0" rpy="0 0 0"/>
      <geometry name="pioneer_geom">
        <mesh filename="package://amr_robots_description/meshes/p3at_meshes/wheel.stl"/>
      </geometry>
      <material name="WheelBlack">
        <color rgba="0.117 0.117 0.117 1"/>
      </material>
    </visual>
    <collision>
      <origin xyz="0 0 0" rpy="${-3.1415927/2.0} 0 0"/>
      <geometry>
        <cylinder radius="0.111" length="0.075"/>
      </geometry>
    </collision>
  </link>

  <gazebo reference="p3at_back_${side}_wheel">
    <material>Gazebo/Black</material>
  </gazebo>

  <joint name="p3at_back_${side}_wheel_joint" type="continuous">
    <axis xyz="0 1 0"/>
    <anchor xyz="0 0 0"/>
    <limit effort="100" velocity="100"/>
    <joint_properties damping="0.7"/>
    <origin xyz="-0.134 ${reflect*0.156} 0.111" rpy="0 0 0"/>
    <parent link="base_link"/>
    <child link="p3at_back_${side}_wheel"/>
  </joint>

  <link name="p3at_front_${side}_wheel">
    <inertial>
      <mass value="1.5"/>
      <origin xyz="0 0 0"/>
      <inertia ixx="0.012411765597" ixy="0" ixz="0"
               iyy="0.015218160428" iyz="0" izz="0.011763977943"/>
    </inertial>
    <visual>
      <origin xyz="0 0 0" rpy="0 0 0"/>
      <geometry name="pioneer_geom">
        <mesh filename="package://amr_robots_description/meshes/p3at_meshes/wheel.stl"/>
      </geometry>
      <material name="WheelBlack">
        <color rgba="0.117 0.117 0.117 1"/>
      </material>
    </visual>
    <collision>
      <origin xyz="0 0 0" rpy="${-3.1415927/2.0} 0 0"/>
      <geometry>
        <cylinder radius="0.111" length="0.075"/>
      </geometry>
    </collision>
  </link>

  <gazebo reference="p3at_front_${side}_wheel">
    <material>Gazebo/Black</material>
  </gazebo>

  <joint name="p3at_front_${side}_wheel_joint" type="continuous">
    <axis xyz="0 1 0"/>
    <anchor xyz="0 0 0"/>
    <limit effort="100" velocity="100"/>
    <joint_properties damping="0.7"/>
    <origin xyz="0.134 ${reflect*0.156} 0.111" rpy="0 0 0"/>
    <parent link="base_link"/>
    <child link="p3at_front_${side}_wheel"/>
  </joint>

  <gazebo reference="p3at_back_${side}_wheel">
    <mu1 value="10.0"/>
    <mu2 value="10.0"/>
    <kp value="100000000.0"/>
    <kd value="1.0"/>
    <fdir1 value="1 0 0"/>
  </gazebo>

  <gazebo reference="p3at_front_${side}_wheel">
    <mu1 value="10.0"/>
    <mu2 value="10.0"/>
    <kp value="100000000.0"/>
    <kd value="1.0"/>
    <fdir1 value="1 0 0"/>
  </gazebo>

  <link name="p3at_back_${side}_axle">
    <inertial>
      <mass value="0.1"/>
      <origin xyz="0 0 0"/>
      <inertia ixx="0.012411765597" ixy="0" ixz="0"
               iyy="0.015218160428" iyz="0" izz="0.011763977943"/>
    </inertial>
    <visual>
      <origin xyz="0 0 0" rpy="0 0 0"/>
      <geometry name="pioneer_geom">
        <box size="0.01 0.01 0.01"/>
      </geometry>
      <material name="AxleGrey">
        <color rgba="0.5 0.5 0.5 1"/>
      </material>
    </visual>
  </link>

  <joint name="p3at_back_${side}_axle_joint" type="fixed">
    <origin xyz="-0.134 ${reflect*0.14} 0.111" rpy="0 0 0"/>
    <parent link="base_link"/>
    <child link="p3at_back_${side}_axle"/>
  </joint>

  <link name="p3at_front_${side}_axle">
    <inertial>
      <mass value="0.1"/>
      <origin xyz="0 0 0"/>
      <inertia ixx="0.012411765597" ixy="0" ixz="0"
               iyy="0.015218160428" iyz="0" izz="0.011763977943"/>
    </inertial>
    <visual>
      <origin xyz="0 0 0" rpy="0 0 0"/>
      <geometry name="pioneer_geom">
        <box size="0.01 0.01 0.01"/>
      </geometry>
      <material name="AxleGrey">
        <color rgba="0.5 0.5 0.5 1"/>
      </material>
    </visual>
  </link>

  <joint name="p3at_front_${side}_axle_joint" type="fixed">
    <origin xyz="0.134 ${reflect*0.14} 0.111" rpy="0 0 0"/>
    <parent link="base_link"/>
    <child link="p3at_front_${side}_axle"/>
  </joint>

  <link name="p3at_back_${side}_hub">
    <inertial>
      <mass value="0.1"/>
      <origin xyz="0 0 0"/>
      <inertia ixx="0.012411765597" ixy="0" ixz="0"
               iyy="0.015218160428" iyz="0" izz="0.011763977943"/>
    </inertial>
    <visual>
      <origin xyz="0 0 0" rpy="0 0 0"/>
      <geometry name="pioneer_geom">
        <mesh filename="package://amr_robots_description/meshes/p3at_meshes/${side}_hubcap.stl"/>
      </geometry>
      <material name="HubcapYellow">
        <color rgba="1.0 0.811 0.151 1.0"/>
      </material>
    </visual>
  </link>

  <gazebo reference="p3at_back_${side}_hub">
    <material>Gazebo/Yellow</material>
  </gazebo>

  <joint name="p3at_back_${side}_hub_joint" type="fixed">
    <origin xyz="-0.134 ${reflect*0.2085} 0.111" rpy="0 0 0"/>
    <parent link="base_link"/>
    <child link="p3at_back_${side}_hub"/>
  </joint>

  <link name="p3at_front_${side}_hub">
    <inertial>
      <mass value="0.1"/>
      <origin xyz="0 0 0"/>
      <inertia ixx="0.012411765597" ixy="0" ixz="0"
               iyy="0.015218160428" iyz="0" izz="0.011763977943"/>
    </inertial>
    <visual>
      <origin xyz="0 0 0" rpy="0 0 0"/>
      <geometry name="pioneer_geom">
        <mesh filename="package://amr_robots_description/meshes/p3at_meshes/${side}_hubcap.stl"/>
      </geometry>
      <material name="HubcapYellow"/>
    </visual>
  </link>

  <gazebo reference="p3at_front_${side}_hub">
    <material>Gazebo/Yellow</material>
  </gazebo>

  <joint name="p3at_front_${side}_hub_joint" type="fixed">
    <origin xyz="0.134 ${reflect*0.2085} 0.111" rpy="0 0 0"/>
    <parent link="base_link"/>
    <child link="p3at_front_${side}_hub"/>
  </joint>

</xacro:macro>

<xacro:macro name="p3at_gazebo_ext">
<gazebo>
  <plugin name="skid_steer_drive_controller" filename="libgazebo_ros_skid_steer_drive.so">
    <updateRate>100.0</updateRate>
    <robotNamespace>sim_p3at</robotNamespace>
    <leftFrontJoint>p3at_front_left_wheel_joint</leftFrontJoint>
    <rightFrontJoint>p3at_front_right_wheel_joint</rightFrontJoint>
    <leftRearJoint>p3at_back_left_wheel_joint</leftRearJoint>
    <rightRearJoint>p3at_back_right_wheel_joint</rightRearJoint>
    <wheelSeparation>0.4</wheelSeparation>
    <wheelDiameter>0.215</wheelDiameter>
    <robotBaseFrame>base_link</robotBaseFrame>
    <MaxForce>5.0</MaxForce>
    <torque>200</torque>
    <commandTopic>cmd_vel</commandTopic>
    <odometryTopic>odom</odometryTopic>
    <odometryFrame>odom</odometryFrame>
    <broadcastTF>1</broadcastTF>
  </plugin>
</gazebo>
</xacro:macro>

<xacro:p3at_drive_side side="left" reflect="1"/>
<xacro:p3at_drive_side side="right" reflect="-1"/>
<xacro:p3at_gazebo_ext/>

  <!-- ================================= -->
  <!-- RealSense D435i - 分离传感器方案 -->
  <!-- ================================= -->
  
  <!-- 1. 引入 RealSense 机械结构 -->
  <xacro:include filename="$(find realsense2_description)/urdf/_d435.urdf.xacro"/>
  
  <!-- 2. 安装到机器人 -->
  <xacro:sensor_d435 parent="base_link" name="camera" use_nominal_extrinsics="true">
    <origin xyz="0.25 0.0 0.45" rpy="0 0 0"/>
  </xacro:sensor_d435>

  <!-- 3. RGB 相机插件 - 挂载到 camera_color_frame -->
  <gazebo reference="camera_color_frame">
    <sensor type="camera" name="color">
      <always_on>true</always_on>
      <update_rate>30.0</update_rate>
      <camera name="camera_color">
        <horizontal_fov>1.211</horizontal_fov>
        <image>
          <width>640</width>
          <height>480</height>
          <format>R8G8B8</format>
        </image>
        <clip>
          <near>0.1</near>
          <far>100</far>
        </clip>
        <noise>
          <type>gaussian</type>
          <mean>0.0</mean>
          <stddev>0.007</stddev>
        </noise>
      </camera>
      <plugin name="color_camera_controller" filename="libgazebo_ros_camera.so">
        <robotNamespace>/sim_p3at</robotNamespace>
        <alwaysOn>true</alwaysOn>
        <updateRate>0.0</updateRate>
        <cameraName>camera/color</cameraName>
        <imageTopicName>image_raw</imageTopicName>
        <cameraInfoTopicName>camera_info</cameraInfoTopicName>
        <frameName>camera_color_optical_frame</frameName>
        <hackBaseline>0.07</hackBaseline>
        <distortionK1>0.0</distortionK1>
        <distortionK2>0.0</distortionK2>
        <distortionK3>0.0</distortionK3>
        <distortionT1>0.0</distortionT1>
        <distortionT2>0.0</distortionT2>
      </plugin>
    </sensor>
  </gazebo>

  <!-- 4. 深度相机插件 - 使用正确的深度格式 -->
  <gazebo reference="camera_depth_frame">
    <sensor type="depth" name="depth">
      <always_on>true</always_on>
      <update_rate>30.0</update_rate>
      <camera name="camera_depth">
        <horizontal_fov>1.211</horizontal_fov>
        <image>
          <width>640</width>
          <height>480</height>
        </image>
        <clip>
          <near>0.1</near>
          <far>10</far>
        </clip>
        <noise>
          <type>gaussian</type>
          <mean>0.0</mean>
          <stddev>0.007</stddev>
        </noise>
      </camera>
      <plugin name="depth_camera_controller" filename="libgazebo_ros_depth_camera.so">
        <robotNamespace>/sim_p3at</robotNamespace>
        <alwaysOn>true</alwaysOn>
        <updateRate>0.0</updateRate>
        <cameraName>camera/depth</cameraName>
        <imageTopicName>image_rect_raw</imageTopicName>
        <cameraInfoTopicName>camera_info</cameraInfoTopicName>
        <pointCloudTopicName>points</pointCloudTopicName>
        <frameName>camera_depth_optical_frame</frameName>
        <pointCloudCutoff>0.2</pointCloudCutoff>
        <pointCloudCutoffMax>10.0</pointCloudCutoffMax>
        <distortionK1>0.0</distortionK1>
        <distortionK2>0.0</distortionK2>
        <distortionK3>0.0</distortionK3>
        <distortionT1>0.0</distortionT1>
        <distortionT2>0.0</distortionT2>
      </plugin>
    </sensor>
  </gazebo>

</robot>
